<?xml version="1.0" encoding="utf-8"?>
<!-- This URDF was automatically created by SolidWorks to URDF Exporter! Originally created by Stephen Brawner (brawner@gmail.com) 
     Commit Version: 1.6.0-4-g7f85cfe  Build Version: 1.6.7995.38578
     For more information, please see http://wiki.ros.org/sw_urdf_exporter -->
<robot
  name="URDF">
  <link
    name="Base_link">
    <inertial>
      <origin
        xyz="0.12824 0.038225 0.045584"
        rpy="0 0 0" />
      <mass
        value="2.20928" />
      <inertia
        ixx="0.0080598"
        ixy="-5.7974E-06"
        ixz="-2.1256E-06"
        iyy="0.0039704"
        iyz="2.6662E-05"
        izz="0.0055375" />
    </inertial>
    <visual>
      <origin
        xyz="0 0 0"
        rpy="0 0 0" />
      <geometry>
        <mesh
          filename="package://URDF/meshes/Base_link.STL" />
      </geometry>
      <material
        name="">
        <color
          rgba="0.75294 0.75294 0.75294 1" />
      </material>
    </visual>
    <collision>
      <origin
        xyz="0 0 0"
        rpy="0 0 0" />
      <geometry>
        <mesh
          filename="package://URDF/meshes/Base_link.STL" />
      </geometry>
    </collision>
  </link>
  <link
    name="Hip_link">
    <inertial>
      <origin
        xyz="0.00034503 -0.013108 0.044177"
        rpy="0 0 0" />
      <mass
        value="1.008" />
      <inertia
        ixx="8.916E-05"
        ixy="-6.9168E-08"
        ixz="-4.6352E-06"
        iyy="0.00018713"
        iyz="-3.0023E-08"
        izz="0.00011382" />
    </inertial>
    <visual>
      <origin
        xyz="0 0 0"
        rpy="0 0 0" />
      <geometry>
        <mesh
          filename="package://URDF/meshes/Hip_link.STL" />
      </geometry>
      <material
        name="">
        <color
          rgba="0.75294 0.75294 0.75294 1" />
      </material>
    </visual>
    <collision>
      <origin
        xyz="0 0 0"
        rpy="0 0 0" />
      <geometry>
        <mesh
          filename="package://URDF/meshes/Hip_link.STL" />
      </geometry>
    </collision>
  </link>
  <joint
    name="Hip_joint"
    type="revolute">
    <origin
      xyz="0 0 0"
      rpy="0 0 0" />
    <parent
      link="Base_link" />
    <child
      link="Hip_link" />
    <axis
      xyz="0 0 -1" />
    <limit
      lower="0.1309"
      upper="3.0107"
      effort="0"
      velocity="0" />
  </joint>
  <link
    name="Thigh_link">
    <inertial>
      <origin
        xyz="-0.091961 0.075591 0.0076548"
        rpy="0 0 0" />
      <mass
        value="2.0083" />
      <inertia
        ixx="0.00082748"
        ixy="1.7039E-05"
        ixz="0.00024101"
        iyy="0.012827"
        iyz="1.1342E-06"
        izz="0.012075" />
    </inertial>
    <visual>
      <origin
        xyz="0 0 0"
        rpy="0 0 0" />
      <geometry>
        <mesh
          filename="package://URDF/meshes/Thigh_link.STL" />
      </geometry>
      <material
        name="">
        <color
          rgba="0.75294 0.75294 0.75294 1" />
      </material>
    </visual>
    <collision>
      <origin
        xyz="0 0 0"
        rpy="0 0 0" />
      <geometry>
        <mesh
          filename="package://URDF/meshes/Thigh_link.STL" />
      </geometry>
    </collision>
  </link>
  <joint
    name="Thigh_joint"
    type="revolute">
    <origin
      xyz="0 0.0082 0.058"
      rpy="0 0 0" />
    <parent
      link="Hip_link" />
    <child
      link="Thigh_link" />
    <axis
      xyz="0 -1 0" />
    <limit
      lower="0.1571"
      upper="6.1359"
      effort="0"
      velocity="0" />
  </joint>
  <link
    name="Calf_link">
    <inertial>
      <origin
        xyz="-0.15293 -0.00023583 -0.011724"
        rpy="0 0 0" />
      <mass
        value="0.53382" />
      <inertia
        ixx="0.00016402"
        ixy="-3.6853E-10"
        ixz="-0.00042607"
        iyy="0.0076992"
        iyz="2.8095E-10"
        izz="0.0075849" />
    </inertial>
    <visual>
      <origin
        xyz="0 0 0"
        rpy="0 0 0" />
      <geometry>
        <mesh
          filename="package://URDF/meshes/Calf_link.STL" />
      </geometry>
      <material
        name="">
        <color
          rgba="0.75294 0.75294 0.75294 1" />
      </material>
    </visual>
    <collision>
      <origin
        xyz="0 0 0"
        rpy="0 0 0" />
      <geometry>
        <mesh
          filename="package://URDF/meshes/Calf_link.STL" />
      </geometry>
    </collision>
  </link>
  <joint
    name="Calf_joint"
    type="revolute">
    <origin
      xyz="-0.35 0.089 0"
      rpy="0 0 0" />
    <parent
      link="Thigh_link" />
    <child
      link="Calf_link" />
    <axis
      xyz="0 -1 0" />
    <limit
      lower="0.3801"
      upper="2.5831"
      effort="0"
      velocity="0" />
  </joint>
  <link
    name="Foot">
    <inertial>
      <origin
        xyz="0.19707 -0.00023583 -0.011724"
        rpy="0 0 0" />
      <mass
        value="0.53382" />
      <inertia
        ixx="0.00016402"
        ixy="-3.6853E-10"
        ixz="-0.00042607"
        iyy="0.0076992"
        iyz="2.8095E-10"
        izz="0.0075849" />
    </inertial>
    <visual>
      <origin
        xyz="0 0 0"
        rpy="0 0 0" />
      <geometry>
        <mesh
          filename="package://URDF/meshes/Foot.STL" />
      </geometry>
      <material
        name="">
        <color
          rgba="0.75294 0.75294 0.75294 1" />
      </material>
    </visual>
    <collision>
      <origin
        xyz="0 0 0"
        rpy="0 0 0" />
      <geometry>
        <mesh
          filename="package://URDF/meshes/Foot.STL" />
      </geometry>
    </collision>
  </link>
  <joint
    name="Foot_point"
    type="fixed">
    <origin
      xyz="-0.35 0 0"
      rpy="0 0 0" />
    <parent
      link="Calf_link" />
    <child
      link="Foot" />
    <axis
      xyz="0 0 0" />
  </joint>
</robot>